WARNING:tensorflow:`period` argument is deprecated. Please use `save_freq` to specify the frequency in number of batches seen.
WARNING  `period` argument is deprecated. Please use `save_freq` to specify the frequency in number of batches seen.
2023-04-03 15:15:11.499921: I tensorflow/core/grappler/devices.cc:66] Number of eligible GPUs (core count >= 8, compute capability >= 0.0): 4
2023-04-03 15:15:11.500187: I tensorflow/core/grappler/clusters/single_machine.cc:357] Starting new session
2023-04-03 15:15:11.532554: I tensorflow/core/common_runtime/gpu/gpu_device.cc:1510] Created device /job:localhost/replica:0/task:0/device:GPU:0 with 78600 MB memory:  -> device: 0, name: NVIDIA A100 80GB PCIe, pci bus id: 0000:17:00.0, compute capability: 8.0
2023-04-03 15:15:11.535151: I tensorflow/core/common_runtime/gpu/gpu_device.cc:1510] Created device /job:localhost/replica:0/task:0/device:GPU:1 with 78600 MB memory:  -> device: 1, name: NVIDIA A100 80GB PCIe, pci bus id: 0000:65:00.0, compute capability: 8.0
2023-04-03 15:15:11.536719: I tensorflow/core/common_runtime/gpu/gpu_device.cc:1510] Created device /job:localhost/replica:0/task:0/device:GPU:2 with 78600 MB memory:  -> device: 2, name: NVIDIA A100 80GB PCIe, pci bus id: 0000:ca:00.0, compute capability: 8.0
2023-04-03 15:15:11.538195: I tensorflow/core/common_runtime/gpu/gpu_device.cc:1510] Created device /job:localhost/replica:0/task:0/device:GPU:3 with 78600 MB memory:  -> device: 3, name: NVIDIA A100 80GB PCIe, pci bus id: 0000:e3:00.0, compute capability: 8.0
2023-04-03 15:15:11.564538: I tensorflow/core/grappler/optimizers/meta_optimizer.cc:1137] Optimization results for grappler item: graph_to_optimize
  function_optimizer: function_optimizer did nothing. time = 0.04ms.
  function_optimizer: function_optimizer did nothing. time = 0.001ms.
WARNING:tensorflow:From /home/zadubrov/.conda/envs/dfpl_exai/lib/python3.9/site-packages/tensorflow/python/ops/math_ops.py:3777: tensor_shape_from_node_def_name (from tensorflow.python.framework.graph_util_impl) is deprecated and will be removed in a future version.
Instructions for updating:
Use `tf.compat.v1.graph_util.tensor_shape_from_node_def_name`
WARNING  From /home/zadubrov/.conda/envs/dfpl_exai/lib/python3.9/site-packages/tensorflow/python/ops/math_ops.py:3777: tensor_shape_from_node_def_name (from tensorflow.python.framework.graph_util_impl) is deprecated and will be removed in a future version.
Instructions for updating:
Use `tf.compat.v1.graph_util.tensor_shape_from_node_def_name`
2023-04-03 15:15:11.980440: I tensorflow/compiler/mlir/mlir_graph_optimization_pass.cc:185] None of the MLIR Optimization Passes are enabled (registered 2)
Epoch 1/10
2023-04-03 15:15:15.621649: I tensorflow/stream_executor/cuda/cuda_blas.cc:1760] TensorFloat-32 will be used for the matrix multiplication. This will only be logged once.
37/37 - 5s - loss: 0.5102 - accuracy: 0.8030 - auc: 0.5291 - precision: 0.2378 - recall: 0.0460 - balanced_accuracy: 0.5067 - val_loss: 0.4506 - val_accuracy: 0.8218 - val_auc: 0.6409 - val_precision: 1.0000 - val_recall: 0.0047 - val_balanced_accuracy: 0.5020
Epoch 2/10
37/37 - 0s - loss: 0.4841 - accuracy: 0.8089 - auc: 0.5883 - precision: 0.3117 - recall: 0.0567 - balanced_accuracy: 0.5135 - val_loss: 0.4291 - val_accuracy: 0.8311 - val_auc: 0.6972 - val_precision: 1.0000 - val_recall: 0.0566 - val_balanced_accuracy: 0.5321
Epoch 3/10
37/37 - 0s - loss: 0.4655 - accuracy: 0.8146 - auc: 0.6242 - precision: 0.4213 - recall: 0.0980 - balanced_accuracy: 0.5355 - val_loss: 0.4148 - val_accuracy: 0.8378 - val_auc: 0.7230 - val_precision: 0.9545 - val_recall: 0.0991 - val_balanced_accuracy: 0.5511
Epoch 4/10
37/37 - 0s - loss: 0.4486 - accuracy: 0.8224 - auc: 0.6623 - precision: 0.5147 - recall: 0.1240 - balanced_accuracy: 0.5482 - val_loss: 0.4051 - val_accuracy: 0.8454 - val_auc: 0.7388 - val_precision: 0.9677 - val_recall: 0.1415 - val_balanced_accuracy: 0.5714
Epoch 5/10
37/37 - 0s - loss: 0.4276 - accuracy: 0.8344 - auc: 0.6958 - precision: 0.6452 - recall: 0.1653 - balanced_accuracy: 0.5706 - val_loss: 0.3964 - val_accuracy: 0.8463 - val_auc: 0.7555 - val_precision: 0.8571 - val_recall: 0.1698 - val_balanced_accuracy: 0.5824
Epoch 6/10
37/37 - 0s - loss: 0.4246 - accuracy: 0.8384 - auc: 0.6998 - precision: 0.6602 - recall: 0.1995 - balanced_accuracy: 0.5899 - val_loss: 0.3899 - val_accuracy: 0.8480 - val_auc: 0.7651 - val_precision: 0.9000 - val_recall: 0.1698 - val_balanced_accuracy: 0.5833
Epoch 7/10
37/37 - 0s - loss: 0.4168 - accuracy: 0.8427 - auc: 0.7108 - precision: 0.6875 - recall: 0.2208 - balanced_accuracy: 0.6001 - val_loss: 0.3849 - val_accuracy: 0.8497 - val_auc: 0.7743 - val_precision: 0.8542 - val_recall: 0.1934 - val_balanced_accuracy: 0.5937
Epoch 8/10
37/37 - 0s - loss: 0.4058 - accuracy: 0.8412 - auc: 0.7348 - precision: 0.6703 - recall: 0.2208 - balanced_accuracy: 0.5994 - val_loss: 0.3807 - val_accuracy: 0.8497 - val_auc: 0.7797 - val_precision: 0.8036 - val_recall: 0.2123 - val_balanced_accuracy: 0.6002
Epoch 9/10
37/37 - 0s - loss: 0.3909 - accuracy: 0.8454 - auc: 0.7641 - precision: 0.7170 - recall: 0.2243 - balanced_accuracy: 0.6031 - val_loss: 0.3778 - val_accuracy: 0.8471 - val_auc: 0.7837 - val_precision: 0.7719 - val_recall: 0.2075 - val_balanced_accuracy: 0.5973
Epoch 10/10
37/37 - 0s - loss: 0.3884 - accuracy: 0.8509 - auc: 0.7639 - precision: 0.7474 - recall: 0.2515 - balanced_accuracy: 0.6191 - val_loss: 0.3735 - val_accuracy: 0.8497 - val_auc: 0.7899 - val_precision: 0.7429 - val_recall: 0.2453 - val_balanced_accuracy: 0.6124
Epoch 00010: val_loss improved from inf to 0.37346, saving model to /home/zadubrov/output/results_train/AR_single-labeled_Fold-0.model.weights.hdf5
INFO     Computation time for training the single-label model for AR: 0.16 min
<IPython.core.display.HTML object>
Traceback (most recent call last):
  File "/home/zadubrov/.conda/envs/dfpl_exai/lib/python3.9/runpy.py", line 197, in _run_module_as_main
    return _run_code(code, main_globals, None,
  File "/home/zadubrov/.conda/envs/dfpl_exai/lib/python3.9/runpy.py", line 87, in _run_code
    exec(code, run_globals)
  File "/gpfs0/home/zadubrov/deepFPlearn_exai/dfpl/__main__.py", line 415, in <module>
    main()
  File "/gpfs0/home/zadubrov/deepFPlearn_exai/dfpl/__main__.py", line 392, in main
    train(fixed_opts)
  File "/gpfs0/home/zadubrov/deepFPlearn_exai/dfpl/__main__.py", line 190, in train
    sl.train_single_label_models(df=df, opts=opts)
  File "/gpfs0/home/zadubrov/deepFPlearn_exai/dfpl/single_label_model.py", line 551, in train_single_label_models
    performance = fit_and_evaluate_model(x_train=x_train, x_test=x_test, y_train=y_train, y_test=y_test,
  File "/gpfs0/home/zadubrov/deepFPlearn_exai/dfpl/single_label_model.py", line 422, in fit_and_evaluate_model
    sd.shap_explain(x_train, model, target, opts.outputDir, drop_values=True, threshold=10, save_values=True)
  File "/gpfs0/home/zadubrov/deepFPlearn_exai/dfpl/shap_dfpl.py", line 20, in shap_explain
    shap_values = explainer(x_train_to_explain)
  File "/home/zadubrov/.conda/envs/dfpl_exai/lib/python3.9/site-packages/shap/explainers/_permutation.py", line 68, in __call__
    return super().__call__(
  File "/home/zadubrov/.conda/envs/dfpl_exai/lib/python3.9/site-packages/shap/explainers/_permutation.py", line 82, in __call__
    return super().__call__(
  File "/home/zadubrov/.conda/envs/dfpl_exai/lib/python3.9/site-packages/shap/explainers/_explainer.py", line 266, in __call__
    row_result = self.explain_row(
  File "/home/zadubrov/.conda/envs/dfpl_exai/lib/python3.9/site-packages/shap/explainers/_permutation.py", line 140, in explain_row
    outputs = fm(masks, zero_index=0, batch_size=batch_size)
  File "/home/zadubrov/.conda/envs/dfpl_exai/lib/python3.9/site-packages/shap/utils/_masked_model.py", line 57, in __call__
    return self._delta_masking_call(masks, zero_index=zero_index, batch_size=batch_size)
  File "/home/zadubrov/.conda/envs/dfpl_exai/lib/python3.9/site-packages/shap/utils/_masked_model.py", line 203, in _delta_masking_call
    outputs = self.model(*subset_masked_inputs)
  File "/home/zadubrov/.conda/envs/dfpl_exai/lib/python3.9/site-packages/shap/models/_model.py", line 26, in __call__
    out = self.inner_model(*args)
  File "/home/zadubrov/.conda/envs/dfpl_exai/lib/python3.9/site-packages/keras/engine/training.py", line 1751, in predict
    tmp_batch_outputs = self.predict_function(iterator)
  File "/home/zadubrov/.conda/envs/dfpl_exai/lib/python3.9/site-packages/tensorflow/python/eager/def_function.py", line 885, in __call__
    result = self._call(*args, **kwds)
  File "/home/zadubrov/.conda/envs/dfpl_exai/lib/python3.9/site-packages/tensorflow/python/eager/def_function.py", line 933, in _call
    self._initialize(args, kwds, add_initializers_to=initializers)
  File "/home/zadubrov/.conda/envs/dfpl_exai/lib/python3.9/site-packages/tensorflow/python/eager/def_function.py", line 759, in _initialize
    self._stateful_fn._get_concrete_function_internal_garbage_collected(  # pylint: disable=protected-access
  File "/home/zadubrov/.conda/envs/dfpl_exai/lib/python3.9/site-packages/tensorflow/python/eager/function.py", line 3066, in _get_concrete_function_internal_garbage_collected
    graph_function, _ = self._maybe_define_function(args, kwargs)
  File "/home/zadubrov/.conda/envs/dfpl_exai/lib/python3.9/site-packages/tensorflow/python/eager/function.py", line 3463, in _maybe_define_function
    graph_function = self._create_graph_function(args, kwargs)
  File "/home/zadubrov/.conda/envs/dfpl_exai/lib/python3.9/site-packages/tensorflow/python/eager/function.py", line 3298, in _create_graph_function
    func_graph_module.func_graph_from_py_func(
  File "/home/zadubrov/.conda/envs/dfpl_exai/lib/python3.9/site-packages/tensorflow/python/framework/func_graph.py", line 1007, in func_graph_from_py_func
    func_outputs = python_func(*func_args, **func_kwargs)
  File "/home/zadubrov/.conda/envs/dfpl_exai/lib/python3.9/site-packages/tensorflow/python/eager/def_function.py", line 668, in wrapped_fn
    out = weak_wrapped_fn().__wrapped__(*args, **kwds)
  File "/home/zadubrov/.conda/envs/dfpl_exai/lib/python3.9/site-packages/tensorflow/python/framework/func_graph.py", line 994, in wrapper
    raise e.ag_error_metadata.to_exception(e)
ValueError: in user code:
    /home/zadubrov/.conda/envs/dfpl_exai/lib/python3.9/site-packages/keras/engine/training.py:1586 predict_function  *
        return step_function(self, iterator)
    /home/zadubrov/.conda/envs/dfpl_exai/lib/python3.9/site-packages/keras/engine/training.py:1576 step_function  **
        outputs = model.distribute_strategy.run(run_step, args=(data,))
    /home/zadubrov/.conda/envs/dfpl_exai/lib/python3.9/site-packages/tensorflow/python/distribute/distribute_lib.py:1286 run
        return self._extended.call_for_each_replica(fn, args=args, kwargs=kwargs)
    /home/zadubrov/.conda/envs/dfpl_exai/lib/python3.9/site-packages/tensorflow/python/distribute/distribute_lib.py:2849 call_for_each_replica
        return self._call_for_each_replica(fn, args, kwargs)
    /home/zadubrov/.conda/envs/dfpl_exai/lib/python3.9/site-packages/tensorflow/python/distribute/distribute_lib.py:3632 _call_for_each_replica
        return fn(*args, **kwargs)
    /home/zadubrov/.conda/envs/dfpl_exai/lib/python3.9/site-packages/keras/engine/training.py:1569 run_step  **
        outputs = model.predict_step(data)
    /home/zadubrov/.conda/envs/dfpl_exai/lib/python3.9/site-packages/keras/engine/training.py:1537 predict_step
        return self(x, training=False)
    /home/zadubrov/.conda/envs/dfpl_exai/lib/python3.9/site-packages/keras/engine/base_layer.py:1020 __call__
        input_spec.assert_input_compatibility(self.input_spec, inputs, self.name)
    /home/zadubrov/.conda/envs/dfpl_exai/lib/python3.9/site-packages/keras/engine/input_spec.py:250 assert_input_compatibility
        raise ValueError(
    ValueError: Input 0 of layer sequential is incompatible with the layer: expected axis -1 of input shape to have value 2048 but received input with shape (None, 1893)